    "exception": "Traceback (most recent call last):\n  File \"/var/task/app.py\", line 19, in lambda_handler\n    cls.import_csv(event)\n  File \"/var/task/common_rds_import/import_csv_base.py\", line 187, in import_csv\n    self.import_csv_data(bucket, key, cur)\n  File \"/var/task/import_csv.py\", line 43, in import_csv_data\n    res = self.df_exec(cur, df, schema, self.chunksize)\n  File \"/var/task/import_csv.py\", line 74, in df_exec\n    extras.execute_values(cur, sql, df_ups.to_numpy().tolist(), page_size=chunksize)\n  File \"/var/task/psycopg2/extras.py\", line 1270, in execute_values\n    cur.execute(b''.join(parts))\npsycopg2.errors.CardinalityViolation: ON CONFLICT DO UPDATE command cannot affect row a second time\nHINT:  Ensure that no rows proposed for insertion within the same command have duplicate constrained values.\n",
